<?xml version="1.0"?>
<robot name="snakebot">

  <link
    name="dummy_link">
  </link>

  <joint
    name="dummy_joint"
    type="fixed">
    <origin xyz="0 0 0" rpy="0 0 0" />
    <parent link="dummy_link"/>
    <child link="base_link"/>
  </joint>

  <link
    name="base_link">
    <visual>
      <origin xyz="0 0 0" rpy="0 0 0" />
      <geometry>
        <mesh
          filename="package://final_v1/meshes/base_link.STL" />
      </geometry>
      <material name="">
        <color rgba="0.792156862745098 0.819607843137255 0.933333333333333 1" />
      </material>
    </visual>
  </link>

  <link name="rod_one">
    <visual>
      <origin xyz="0 0 0" rpy="0 0 0" />
      <geometry>
        <mesh
          filename="package://final_v1/meshes/rod_one.STL" />
      </geometry>
      <material name="">
        <color rgba="0.792156862745098 0.819607843137255 0.933333333333333 1" />
      </material>
    </visual>
  </link>

  <joint
    name="rod_one_joint"
    type="revolute">
    <origin xyz="0.2159 0 0" rpy="3.1416 0 0" />
    <parent link="base_link" />
    <child link="rod_one" />
    <axis xyz="0 1 0" />
    <limit
      lower="-3.14"
      upper="3.14"
      effort="1000"
      velocity="0.1" />
  </joint>

  <link
    name="link_one">
    <visual>
      <origin xyz="0 0 0" rpy="0 0 0" />
      <geometry>
        <mesh
          filename="package://final_v1/meshes/link_one.STL" />
      </geometry>
      <material name="">
        <color rgba="0.792156862745098 0.819607843137255 0.933333333333333 1" />
      </material>
    </visual>
  </link>

  <joint
    name="link_one_joint"
    type="fixed">
    <origin xyz="0 0 0" rpy="-1.5708 0 0" />
    <parent link="rod_one" />
    <child link="link_one" />
    <axis xyz="0 0 1" />
  </joint>

  <link name="rod_three">
    <visual>
      <origin xyz="0 0 0" rpy="0 0 0" />
      <geometry>
        <mesh
          filename="package://final_v1/meshes/rod_three.STL" />
      </geometry>
      <material name="">
        <color rgba="0.792156862745098 0.819607843137255 0.933333333333333 1" />
      </material>
    </visual>
  </link>

  <joint
    name="rod_three_joint"
    type="revolute">
    <origin xyz="0.2159 0 0.03175" rpy="0 0 0" />
    <parent link="link_one" />
    <child link="rod_three" />
    <axis xyz="0 1 0" />
    <limit
      lower="-3.14"
      upper="3.14"
      effort="1000"
      velocity="0.1" />
  </joint>

  <link name="link_two">
    <visual>
      <origin xyz="0 0 0" rpy="0 0 0" />
      <geometry>
        <mesh filename="package://final_v1/meshes/link_two.STL" />
      </geometry>
      <material name="">
        <color rgba="0.792156862745098 0.819607843137255 0.933333333333333 1" />
      </material>
    </visual>
  </link>

  <joint
    name="link_two_joint"
    type="fixed">
    <origin xyz="0 0 0" rpy="1.5708 0 0" />
    <parent link="rod_three" />
    <child link="link_two" />
    <axis xyz="0 0 1" />
  </joint>

  <link name="rod_four">
    <visual>
      <origin xyz="0 0 0" rpy="0 0 0" />
      <geometry>
        <mesh filename="package://final_v1/meshes/rod_four.STL" />
      </geometry>
      <material name="">
        <color rgba="0.792156862745098 0.819607843137255 0.933333333333333 1" />
      </material>
    </visual>
  </link>

  <joint
    name="rod_four_joint"
    type="revolute">
    <origin xyz="0.2159 0 0" rpy="0 -0.042207 0" />
    <parent link="link_two" />
    <child link="rod_four" />
    <axis xyz="0 1 0" />
    <limit
      lower="-3.14"
      upper="3.14"
      effort="1000"
      velocity="0.1" />
  </joint>

  <link
    name="link_three">
    <visual>
      <origin xyz="0 0 0" rpy="0 0 0" />
      <geometry>
        <mesh filename="package://final_v1/meshes/link_three.STL" />
      </geometry>
      <material name="">
        <color rgba="0.792156862745098 0.819607843137255 0.933333333333333 1" />
      </material>
    </visual>
  </link>

  <joint
    name="link_three_joint"
    type="fixed">
    <origin xyz="0 0 0" rpy="-1.5708 0.042207 0" />
    <parent link="rod_four" />
    <child link="link_three" />
    <axis xyz="0 0 1" />
  </joint>

  <link name="rod_five">
    <visual>
      <origin xyz="0 0 0" rpy="0 0 0" />
      <geometry>
        <mesh filename="package://final_v1/meshes/rod_five.STL" />
      </geometry>
      <material name="">
        <color rgba="0.792156862745098 0.819607843137255 0.933333333333333 1" />
      </material>
    </visual>
  </link>

  <joint
    name="rod_five_joint"
    type="revolute">
    <origin xyz="0.2159 0 0" rpy="0 0 0" />
    <parent link="link_three" />
    <child link="rod_five" />
    <axis xyz="0 1 0" />
    <limit
      lower="-3.14"
      upper="3.14"
      effort="1000"
      velocity="0.1" />
  </joint>

  <link name="link_four">
    <visual>
      <origin xyz="0 0 0" rpy="0 0 0" />
      <geometry>
        <mesh filename="package://final_v1/meshes/link_four.STL" />
      </geometry>
      <material name="">
        <color rgba="0.792156862745098 0.819607843137255 0.933333333333333 1" />
      </material>
    </visual>
  </link>

  <joint
    name="link_four_joint"
    type="fixed">
    <origin xyz="0 0 0" rpy="1.5708 0 0" />
    <parent link="rod_five" />
    <child link="link_four" />
    <axis xyz="0 0 1" />
  </joint>
  
  <link
    name="rod_six">
    <visual>
      <origin xyz="0 0 0" rpy="0 0 0" />
      <geometry>
        <mesh filename="package://final_v1/meshes/rod_six.STL" />
      </geometry>
      <material name="">
        <color rgba="0.792156862745098 0.819607843137255 0.933333333333333 1" />
      </material>
    </visual>
  </link>

  <joint
    name="rod_six_joint"
    type="revolute">
    <origin xyz="0.2159 0 0" rpy="0 0 0" />
    <parent link="link_four" />
    <child link="rod_six" />
    <axis xyz="0 1 0" />
    <limit
      lower="-3.14"
      upper="3.14"
      effort="1000"
      velocity="0.1" />
  </joint>

  <link name="link_five">
    <visual>
      <origin xyz="0 0 0" rpy="0 0 0" />
      <geometry>
        <mesh filename="package://final_v1/meshes/link_five.STL" />
      </geometry>
      <material name="">
        <color rgba="0.792156862745098 0.819607843137255 0.933333333333333 1" />
      </material>
    </visual>
  </link>

  <joint
    name="link_five_joint"
    type="fixed">
    <origin xyz="0 0.01 0" rpy="-1.5708 0 0" />
    <parent link="rod_six" />
    <child link="link_five" />
    <axis xyz="0 0 1" />
  </joint>

  <link name="rod_seven">
    <visual>
      <origin xyz="0 0 0" rpy="0 0 0" />
      <geometry>
        <mesh filename="package://final_v1/meshes/rod_seven.STL" />
      </geometry>
      <material name="">
        <color rgba="0.792156862745098 0.819607843137255 0.933333333333333 1" />
      </material>
    </visual>
  </link>

  <joint
    name="rod_seven_joint"
    type="revolute">
    <origin xyz="0.2159 0 -0.01" rpy="0 0 0" />
    <parent link="link_five" />
    <child link="rod_seven" />
    <axis xyz="0 1 0" />
    <limit
      lower="-3.14"
      upper="3.14"
      effort="1000"
      velocity="0.1" />
  </joint>

  <link name="link_six">
    <visual>
      <origin xyz="0 0 0" rpy="0 0 0" />
      <geometry>
        <mesh filename="package://final_v1/meshes/link_six.STL" />
      </geometry>
      <material name="">
        <color rgba="0.792156862745098 0.819607843137255 0.933333333333333 1" />
      </material>
    </visual>
  </link>

  <joint
    name="link_six_joint"
    type="fixed">
    <origin
      xyz="0 0 0"
      rpy="1.5708 0 0" />
    <parent
      link="rod_seven" />
    <child
      link="link_six" />
    <axis
      xyz="0 0 1" />
  </joint>
  <link
    name="rod_eight">
    <inertial>
      <origin
        xyz="-2.22044604925031E-16 -1.14491749414469E-15 -2.50000002532371E-07"
        rpy="0 0 0" />
      <mass
        value="0.0918944415792056" />
      <inertia
        ixx="0.000255192786793956"
        ixy="-4.3123656691029E-36"
        ixz="1.87029967423402E-38"
        iyy="1.7374964708254E-05"
        iyz="4.48418013055967E-19"
        izz="0.000255192786793956" />
    </inertial>
    <visual>
      <origin
        xyz="0 0 0"
        rpy="0 0 0" />
      <geometry>
        <mesh
          filename="package://final_v1/meshes/rod_eight.STL" />
      </geometry>
      <material
        name="">
        <color
          rgba="0.792156862745098 0.819607843137255 0.933333333333333 1" />
      </material>
    </visual>
    <collision>
      <origin
        xyz="0 0 0"
        rpy="0 0 0" />
      <geometry>
        <mesh
          filename="package://final_v1/meshes/rod_eight.STL" />
      </geometry>
    </collision>
  </link>
  <joint
    name="rod_eight_joint"
    type="revolute">
    <origin
      xyz="0.2159 0 0"
      rpy="0 0 0" />
    <parent
      link="link_six" />
    <child
      link="rod_eight" />
    <axis
      xyz="0 1 0" />
    <limit
      lower="-3.14"
      upper="3.14"
      effort="1000"
      velocity="0.1" />
  </joint>
  <link
    name="link_seven">
    <inertial>
      <origin
        xyz="0.108134816869862 2.50000001378728E-07 -0.010000000000001"
        rpy="0 0 0" />
      <mass
        value="0.372498080839687" />
      <inertia
        ixx="0.40127571298329474"
        ixy="-1.75754446222009E-18"
        ixz="3.76084450963196E-20"
        iyy="0.40265498440151005"
        iyz="5.41436837192336E-19"
        izz="0.20234553145484644" />
    </inertial>
    <visual>
      <origin
        xyz="0 0 0"
        rpy="0 0 0" />
      <geometry>
        <mesh
          filename="package://final_v1/meshes/link_seven.STL" />
      </geometry>
      <material
        name="">
        <color
          rgba="0.792156862745098 0.819607843137255 0.933333333333333 1" />
      </material>
    </visual>
    <collision>
      <origin
        xyz="0 0 0"
        rpy="0 0 0" />
      <geometry>
        <mesh
          filename="package://final_v1/meshes/link_seven.STL" />
      </geometry>
    </collision>
  </link>
  <joint
    name="link_seven_joint"
    type="fixed">
    <origin
      xyz="0 0.01 0"
      rpy="-1.5708 0 0" />
    <parent
      link="rod_eight" />
    <child
      link="link_seven" />
    <axis
      xyz="0 0 1" />
  </joint>
  <link
    name="rod_nine">
    <inertial>
      <origin
        xyz="0 2.50000001519868E-07 -2.77555756156289E-17"
        rpy="0 0 0" />
      <mass
        value="0.0918944415792055" />
      <inertia
        ixx="0.000255192786793957"
        ixy="-2.25062568663077E-35"
        ixz="2.02955234186625E-38"
        iyy="1.73749647082541E-05"
        iyz="4.4723784443819E-36"
        izz="0.000255192786793957" />
    </inertial>
    <visual>
      <origin
        xyz="0 0 0"
        rpy="0 0 0" />
      <geometry>
        <mesh
          filename="package://final_v1/meshes/rod_nine.STL" />
      </geometry>
      <material
        name="">
        <color
          rgba="0.792156862745098 0.819607843137255 0.933333333333333 1" />
      </material>
    </visual>
    <collision>
      <origin
        xyz="0 0 0"
        rpy="0 0 0" />
      <geometry>
        <mesh
          filename="package://final_v1/meshes/rod_nine.STL" />
      </geometry>
    </collision>
  </link>
  <joint
    name="rod_nine_joint"
    type="revolute">
    <origin
      xyz="0.2159 0 -0.01"
      rpy="0 0 0" />
    <parent
      link="link_seven" />
    <child
      link="rod_nine" />
    <axis
      xyz="0 1 0" />
    <limit
      lower="-3.14"
      upper="3.14"
      effort="1000"
      velocity="0.1" />
  </joint>
  <link
    name="link_eight">
    <inertial>
      <origin
        xyz="0.108134816869862 1.36002320516582E-15 -2.50000001541354E-07"
        rpy="0 0 0" />
      <mass
        value="0.372498080839687" />
      <inertia
        ixx="0.40127571298329474"
        ixy="2.89151640615346E-17"
        ixz="1.53457755603158E-19"
        iyy="0.40265498440151005"
        iyz="7.09252310864723E-19"
        izz="0.20234553145484644" />
    </inertial>
    <visual>
      <origin
        xyz="0 0 0"
        rpy="0 0 0" />
      <geometry>
        <mesh
          filename="package://final_v1/meshes/link_eight.STL" />
      </geometry>
      <material
        name="">
        <color
          rgba="0.792156862745098 0.819607843137255 0.933333333333333 1" />
      </material>
    </visual>
    <collision>
      <origin
        xyz="0 0 0"
        rpy="0 0 0" />
      <geometry>
        <mesh
          filename="package://final_v1/meshes/link_eight.STL" />
      </geometry>
    </collision>
  </link>
  <joint
    name="link_eight_joint"
    type="fixed">
    <origin
      xyz="0 0 0"
      rpy="1.5708 0 0" />
    <parent
      link="rod_nine" />
    <child
      link="link_eight" />
    <axis
      xyz="0 0 1" />
  </joint>
  <link
    name="rod_ten">
    <inertial>
      <origin
        xyz="4.44089209850063E-16 1.4432899320127E-15 -2.5000000142519E-07"
        rpy="0 0 0" />
      <mass
        value="0.0918944415792056" />
      <inertia
        ixx="0.000255192786793957"
        ixy="-2.25062568663077E-35"
        ixz="2.02955234186611E-38"
        iyy="1.73749647082541E-05"
        iyz="-1.45616607989176E-20"
        izz="0.000255192786793957" />
    </inertial>
    <visual>
      <origin
        xyz="0 0 0"
        rpy="0 0 0" />
      <geometry>
        <mesh
          filename="package://final_v1/meshes/rod_ten.STL" />
      </geometry>
      <material
        name="">
        <color
          rgba="0.792156862745098 0.819607843137255 0.933333333333333 1" />
      </material>
    </visual>
    <collision>
      <origin
        xyz="0 0 0"
        rpy="0 0 0" />
      <geometry>
        <mesh
          filename="package://final_v1/meshes/rod_ten.STL" />
      </geometry>
    </collision>
  </link>
  <joint
    name="rod_ten_joint"
    type="revolute">
    <origin
      xyz="0.2159 0 0"
      rpy="0 0 0" />
    <parent
      link="link_eight" />
    <child
      link="rod_ten" />
    <axis
      xyz="0 1 0" />
    <limit
      lower="-3.14"
      upper="3.14"
      effort="1000"
      velocity="0.1" />
  </joint>
  <link
    name="link_nine">
    <inertial>
      <origin
        xyz="0.108134816869861 2.50000001460126E-07 1.38777878078145E-15"
        rpy="0 0 0" />
      <mass
        value="0.372498080839687" />
      <inertia
        ixx="0.40127571298329474"
        ixy="-1.74321646306959E-18"
        ixz="3.56337937219194E-21"
        iyy="0.40265498440151005"
        iyz="5.41436672825334E-19"
        izz="0.20234553145484644" />
    </inertial>
    <visual>
      <origin
        xyz="0 0 0"
        rpy="0 0 0" />
      <geometry>
        <mesh
          filename="package://final_v1/meshes/link_nine.STL" />
      </geometry>
      <material
        name="">
        <color
          rgba="0.792156862745098 0.819607843137255 0.933333333333333 1" />
      </material>
    </visual>
    <collision>
      <origin
        xyz="0 0 0"
        rpy="0 0 0" />
      <geometry>
        <mesh
          filename="package://final_v1/meshes/link_nine.STL" />
      </geometry>
    </collision>
  </link>
  <joint
    name="link_nine_joint"
    type="fixed">
    <origin
      xyz="0 0 0"
      rpy="-1.5708 0 0" />
    <parent
      link="rod_ten" />
    <child
      link="link_nine" />
    <axis
      xyz="0 0 1" />
  </joint>
  <link
    name="rod_eleven">
    <inertial>
      <origin
        xyz="4.44089209850063E-16 2.50000001408845E-07 -1.38777878078145E-17"
        rpy="0 0 0" />
      <mass
        value="0.0918944415792056" />
      <inertia
        ixx="0.000255192786793957"
        ixy="-2.25062568663077E-35"
        ixz="2.02955234186625E-38"
        iyy="1.73749647082541E-05"
        iyz="0"
        izz="0.000255192786793957" />
    </inertial>
    <visual>
      <origin
        xyz="0 0 0"
        rpy="0 0 0" />
      <geometry>
        <mesh
          filename="package://final_v1/meshes/rod_eleven.STL" />
      </geometry>
      <material
        name="">
        <color
          rgba="0.792156862745098 0.819607843137255 0.933333333333333 1" />
      </material>
    </visual>
    <collision>
      <origin
        xyz="0 0 0"
        rpy="0 0 0" />
      <geometry>
        <mesh
          filename="package://final_v1/meshes/rod_eleven.STL" />
      </geometry>
    </collision>
  </link>
  <joint
    name="rod_eleven_joint"
    type="revolute">
    <origin
      xyz="0.2159 0 0"
      rpy="0 0 0" />
    <parent
      link="link_nine" />
    <child
      link="rod_eleven" />
    <axis
      xyz="0 1 0" />
    <limit
      lower="-3.14"
      upper="3.14"
      effort="1000"
      velocity="0.1" />
  </joint>
  <link
    name="link_ten">
    <inertial>
      <origin
        xyz="0.108134816869861 2.77555756156289E-17 -2.50000001320092E-07"
        rpy="0 0 0" />
      <mass
        value="0.372498080839687" />
      <inertia
        ixx="0.40127571298329474"
        ixy="2.88455757760997E-17"
        ixz="1.08485666298947E-19"
        iyy="0.40265498440151005"
        iyz="7.09252192824713E-19"
        izz="0.20234553145484644" />
    </inertial>
    <visual>
      <origin
        xyz="0 0 0"
        rpy="0 0 0" />
      <geometry>
        <mesh
          filename="package://final_v1/meshes/link_ten.STL" />
      </geometry>
      <material
        name="">
        <color
          rgba="0.792156862745098 0.819607843137255 0.933333333333333 1" />
      </material>
    </visual>
    <collision>
      <origin
        xyz="0 0 0"
        rpy="0 0 0" />
      <geometry>
        <mesh
          filename="package://final_v1/meshes/link_ten.STL" />
      </geometry>
    </collision>
  </link>
  <joint
    name="link_ten_joint"
    type="fixed">
    <origin
      xyz="0 0 0"
      rpy="1.5708 0 0" />
    <parent
      link="rod_eleven" />
    <child
      link="link_ten" />
    <axis
      xyz="0 0 1" />
  </joint>
</robot>