<?xml version="1.0" ?>
<!-- =================================================================================== -->
<!-- |    This document was autogenerated by xacro from snakebot.urdf.xacro            | -->
<!-- |    EDITING THIS FILE BY HAND IS NOT RECOMMENDED                                 | -->
<!-- =================================================================================== -->
<robot name="snakebot">

  <!-- *************************************************** -->
  <!-- ******************* RVIZ Colors ******************* -->
  <!-- *************************************************** -->

  <material name="white">    <color rgba="1.00 1.00 1.00 1"/>  </material>
  <material name="gray">     <color rgba="0.60 0.60 0.60 1"/>  </material>
  <material name="table">    <color rgba="0.85 0.77 0.77 1"/>  </material>
  <material name="black">    <color rgba="0.00 0.00 0.00 1"/>  </material>

  <material name="red">      <color rgba="1.00 0.00 0.00 1"/>  </material>
  <material name="green">    <color rgba="0.00 1.00 0.00 1"/>  </material>
  <material name="blue">     <color rgba="0.00 0.00 1.00 1"/>  </material>

  <material name="cyan">     <color rgba="0.00 1.00 1.00 1"/>  </material>
  <material name="magenta">  <color rgba="1.00 0.00 1.00 1"/>  </material>
  <material name="yellow">   <color rgba="1.00 1.00 0.00 1"/>  </material>

  <material name="orange">   <color rgba="1.00 0.65 0.00 1"/>  </material>



  <!-- *************************************************** -->
  <!-- ******************* PARAMETERS ******************** -->
  <!-- *************************************************** -->
  <material name="Grey">
    <color rgba="0.4 0.4 0.4 1.0"/>
  </material>
  <material name="Red">
    <color rgba="0.82 0.06 0.06 1.0"/>
  </material>
  <material name="Orange">
    <color rgba="1.0 0.4235294117647059 0.0392156862745098 1.0"/>
  </material>
  <!-- *************************************************** -->
  <!-- ******************** BASE MACRO ******************* -->
  <!-- *************************************************** -->
  <!-- *************************************************** -->
  <!-- *************** PAIR OF JOINTS MACRO ************** -->
  <!-- *************************************************** -->
  <!-- *************************************************** -->
  <!-- ***************** TIP FLANGE MACRO **************** -->
  <!-- *************************************************** -->
  <!-- *************************************************** -->
  <!-- ********************** ROBOT ********************** -->
  <!-- *************************************************** -->
  <link name="world"/>
  <joint name="attach-base" type="fixed">
    <parent link="world"/>
    <child link="link0b"/>
    <origin  xyz="0 0 0"  rpy="0 0 0" />
  </joint>
  <link name="link0b">
    <visual>
      <geometry>
        <mesh filename="package://snakebot/meshes/base.stl"/>
      </geometry>
      <material name="Grey"/>
    </visual>
  </link>
  <joint name="shift0" type="fixed">
    <parent link="link0b"/>
    <child link="link0c"/>
    <origin rpy="0 0 0" xyz="0 0 0.1575"/>
  </joint>
  <link name="link0c">
    </link>
  <joint name="joint1a" type="continuous">
    <parent link="link0c"/>
    <child link="link1a"/>
    <origin rpy="0 0 3.141592653589793" xyz="0 0 0"/>
    <axis xyz="0 0 1"/>
  </joint>
  <link name="link1a">
    <inertial>
      <origin rpy="0 0 0" xyz="0 -0.03 0.12"/>
      <mass value="4"/>
      <inertia ixx="0.1" ixy="0" ixz="0" iyy="0.09" iyz="0" izz="0.02"/>
    </inertial>
    <visual>
      <origin rpy="0 0 0" xyz="0 0 0"/>
      <geometry>
        <mesh filename="package://snakebot/meshes/link.stl"/>
      </geometry>
      <material name="Orange"/>
    </visual>
  </link>
  <joint name="joint1b" type="continuous">
    <parent link="link1a"/>
    <child link="link1b"/>
    <origin rpy="0 0 0" xyz="0 0 0.2025"/>
    <axis xyz="0 1 0"/>
  </joint>
  <link name="link1b">
    <inertial>
      <origin rpy="3.141592653589793 0 0" xyz="0 0.03 0.08250000000000002"/>
      <mass value="4"/>
      <inertia ixx="0.1" ixy="0" ixz="0" iyy="0.09" iyz="0" izz="0.02"/>
    </inertial>
    <visual>
      <origin rpy="3.141592653589793 0 0" xyz="0 0 0.2025"/>
      <geometry>
        <mesh filename="package://snakebot/meshes/link.stl"/>
      </geometry>
      <material name="Orange"/>
    </visual>
  </link>
  <joint name="shift1" type="fixed">
    <parent link="link1b"/>
    <child link="link1c"/>
    <origin rpy="0 0 0" xyz="0 0 0.2025"/>
  </joint>
  <link name="link1c">
    </link>
  <joint name="joint2a" type="continuous">
    <parent link="link1c"/>
    <child link="link2a"/>
    <origin rpy="0 0 3.141592653589793" xyz="0 0 0"/>
    <axis xyz="0 0 1"/>
  </joint>
  <link name="link2a">
    <inertial>
      <origin rpy="0 0 0" xyz="0 -0.03 0.12"/>
      <mass value="4"/>
      <inertia ixx="0.1" ixy="0" ixz="0" iyy="0.09" iyz="0" izz="0.02"/>
    </inertial>
    <visual>
      <origin rpy="0 0 0" xyz="0 0 0"/>
      <geometry>
        <mesh filename="package://snakebot/meshes/link.stl"/>
      </geometry>
      <material name="Orange"/>
    </visual>
  </link>
  <joint name="joint2b" type="continuous">
    <parent link="link2a"/>
    <child link="link2b"/>
    <origin rpy="0 0 0" xyz="0 0 0.2025"/>
    <axis xyz="0 1 0"/>
  </joint>
  <link name="link2b">
    <inertial>
      <origin rpy="3.141592653589793 0 0" xyz="0 0.03 0.08250000000000002"/>
      <mass value="4"/>
      <inertia ixx="0.1" ixy="0" ixz="0" iyy="0.09" iyz="0" izz="0.02"/>
    </inertial>
    <visual>
      <origin rpy="3.141592653589793 0 0" xyz="0 0 0.2025"/>
      <geometry>
        <mesh filename="package://snakebot/meshes/link.stl"/>
      </geometry>
      <material name="Orange"/>
    </visual>
  </link>
  <joint name="shift2" type="fixed">
    <parent link="link2b"/>
    <child link="link2c"/>
    <origin rpy="0 0 0" xyz="0 0 0.2025"/>
  </joint>
  <link name="link2c">
    </link>
  <joint name="joint3a" type="continuous">
    <parent link="link2c"/>
    <child link="link3a"/>
    <origin rpy="0 0 3.141592653589793" xyz="0 0 0"/>
    <axis xyz="0 0 1"/>
  </joint>
  <link name="link3a">
    <inertial>
      <origin rpy="0 0 0" xyz="0 -0.03 0.12"/>
      <mass value="4"/>
      <inertia ixx="0.1" ixy="0" ixz="0" iyy="0.09" iyz="0" izz="0.02"/>
    </inertial>
    <visual>
      <origin rpy="0 0 0" xyz="0 0 0"/>
      <geometry>
        <mesh filename="package://snakebot/meshes/link.stl"/>
      </geometry>
      <material name="Orange"/>
    </visual>
  </link>
  <joint name="joint3b" type="continuous">
    <parent link="link3a"/>
    <child link="link3b"/>
    <origin rpy="0 0 0" xyz="0 0 0.2025"/>
    <axis xyz="0 1 0"/>
  </joint>
  <link name="link3b">
    <inertial>
      <origin rpy="3.141592653589793 0 0" xyz="0 0.03 0.08250000000000002"/>
      <mass value="4"/>
      <inertia ixx="0.1" ixy="0" ixz="0" iyy="0.09" iyz="0" izz="0.02"/>
    </inertial>
    <visual>
      <origin rpy="3.141592653589793 0 0" xyz="0 0 0.2025"/>
      <geometry>
        <mesh filename="package://snakebot/meshes/link.stl"/>
      </geometry>
      <material name="Orange"/>
    </visual>
  </link>
  <joint name="shift3" type="fixed">
    <parent link="link3b"/>
    <child link="link3c"/>
    <origin rpy="0 0 0" xyz="0 0 0.2025"/>
  </joint>
  <link name="link3c">
    </link>
  <joint name="joint4a" type="continuous">
    <parent link="link3c"/>
    <child link="link4a"/>
    <origin rpy="0 0 3.141592653589793" xyz="0 0 0"/>
    <axis xyz="0 0 1"/>
  </joint>
  <link name="link4a">
    <inertial>
      <origin rpy="0 0 0" xyz="0 -0.03 0.12"/>
      <mass value="4"/>
      <inertia ixx="0.1" ixy="0" ixz="0" iyy="0.09" iyz="0" izz="0.02"/>
    </inertial>
    <visual>
      <origin rpy="0 0 0" xyz="0 0 0"/>
      <geometry>
        <mesh filename="package://snakebot/meshes/link.stl"/>
      </geometry>
      <material name="Orange"/>
    </visual>
  </link>
  <joint name="joint4b" type="continuous">
    <parent link="link4a"/>
    <child link="link4b"/>
    <origin rpy="0 0 0" xyz="0 0 0.2025"/>
    <axis xyz="0 1 0"/>
  </joint>
  <link name="link4b">
    <inertial>
      <origin rpy="3.141592653589793 0 0" xyz="0 0.03 0.08250000000000002"/>
      <mass value="4"/>
      <inertia ixx="0.1" ixy="0" ixz="0" iyy="0.09" iyz="0" izz="0.02"/>
    </inertial>
    <visual>
      <origin rpy="3.141592653589793 0 0" xyz="0 0 0.2025"/>
      <geometry>
        <mesh filename="package://snakebot/meshes/link.stl"/>
      </geometry>
      <material name="Orange"/>
    </visual>
  </link>
  <joint name="shift4" type="fixed">
    <parent link="link4b"/>
    <child link="link4c"/>
    <origin rpy="0 0 0" xyz="0 0 0.2025"/>
  </joint>
  <link name="link4c">
    </link>
  <joint name="joint5a" type="continuous">
    <parent link="link4c"/>
    <child link="link5a"/>
    <origin rpy="0 0 3.141592653589793" xyz="0 0 0"/>
    <axis xyz="0 0 1"/>
  </joint>
  <link name="link5a">
    <inertial>
      <origin rpy="0 0 0" xyz="0 -0.03 0.12"/>
      <mass value="4"/>
      <inertia ixx="0.1" ixy="0" ixz="0" iyy="0.09" iyz="0" izz="0.02"/>
    </inertial>
    <visual>
      <origin rpy="0 0 0" xyz="0 0 0"/>
      <geometry>
        <mesh filename="package://snakebot/meshes/link.stl"/>
      </geometry>
      <material name="Orange"/>
    </visual>
  </link>
  <joint name="joint5b" type="continuous">
    <parent link="link5a"/>
    <child link="link5b"/>
    <origin rpy="0 0 0" xyz="0 0 0.2025"/>
    <axis xyz="0 1 0"/>
  </joint>
  <link name="link5b">
    <inertial>
      <origin rpy="3.141592653589793 0 0" xyz="0 0.03 0.08250000000000002"/>
      <mass value="4"/>
      <inertia ixx="0.1" ixy="0" ixz="0" iyy="0.09" iyz="0" izz="0.02"/>
    </inertial>
    <visual>
      <origin rpy="3.141592653589793 0 0" xyz="0 0 0.2025"/>
      <geometry>
        <mesh filename="package://snakebot/meshes/link.stl"/>
      </geometry>
      <material name="Orange"/>
    </visual>
  </link>
  <joint name="shift5" type="fixed">
    <parent link="link5b"/>
    <child link="link5c"/>
    <origin rpy="0 0 0" xyz="0 0 0.2025"/>
  </joint>
  <link name="link5c">
    </link>
  <joint name="joint6a" type="continuous">
    <parent link="link5c"/>
    <child link="link6a"/>
    <origin rpy="0 0 3.141592653589793" xyz="0 0 0"/>
    <axis xyz="0 0 1"/>
  </joint>
  <link name="link6a">
    <inertial>
      <origin rpy="0 0 0" xyz="0 -0.03 0.12"/>
      <mass value="4"/>
      <inertia ixx="0.1" ixy="0" ixz="0" iyy="0.09" iyz="0" izz="0.02"/>
    </inertial>
    <visual>
      <origin rpy="0 0 0" xyz="0 0 0"/>
      <geometry>
        <mesh filename="package://snakebot/meshes/link.stl"/>
      </geometry>
      <material name="Orange"/>
    </visual>
  </link>
  <joint name="joint6b" type="continuous">
    <parent link="link6a"/>
    <child link="link6b"/>
    <origin rpy="0 0 0" xyz="0 0 0.2025"/>
    <axis xyz="0 1 0"/>
  </joint>
  <link name="link6b">
    <inertial>
      <origin rpy="3.141592653589793 0 0" xyz="0 0.03 0.08250000000000002"/>
      <mass value="4"/>
      <inertia ixx="0.1" ixy="0" ixz="0" iyy="0.09" iyz="0" izz="0.02"/>
    </inertial>
    <visual>
      <origin rpy="3.141592653589793 0 0" xyz="0 0 0.2025"/>
      <geometry>
        <mesh filename="package://snakebot/meshes/link.stl"/>
      </geometry>
      <material name="Orange"/>
    </visual>
  </link>
  <joint name="shift6" type="fixed">
    <parent link="link6b"/>
    <child link="link6c"/>
    <origin rpy="0 0 0" xyz="0 0 0.2025"/>
  </joint>
  <link name="link6c">
    </link>
  <joint name="joint7a" type="continuous">
    <parent link="link6c"/>
    <child link="link7a"/>
    <origin rpy="0 0 3.141592653589793" xyz="0 0 0"/>
    <axis xyz="0 0 1"/>
  </joint>
  <link name="link7a">
    <inertial>
      <origin rpy="0 0 0" xyz="0 -0.03 0.12"/>
      <mass value="4"/>
      <inertia ixx="0.1" ixy="0" ixz="0" iyy="0.09" iyz="0" izz="0.02"/>
    </inertial>
    <visual>
      <origin rpy="0 0 0" xyz="0 0 0"/>
      <geometry>
        <mesh filename="package://snakebot/meshes/link.stl"/>
      </geometry>
      <material name="Orange"/>
    </visual>
  </link>
  <joint name="joint7b" type="continuous">
    <parent link="link7a"/>
    <child link="link7b"/>
    <origin rpy="0 0 0" xyz="0 0 0.2025"/>
    <axis xyz="0 1 0"/>
  </joint>
  <link name="link7b">
    <inertial>
      <origin rpy="3.141592653589793 0 0" xyz="0 0.03 0.08250000000000002"/>
      <mass value="4"/>
      <inertia ixx="0.1" ixy="0" ixz="0" iyy="0.09" iyz="0" izz="0.02"/>
    </inertial>
    <visual>
      <origin rpy="3.141592653589793 0 0" xyz="0 0 0.2025"/>
      <geometry>
        <mesh filename="package://snakebot/meshes/link.stl"/>
      </geometry>
      <material name="Orange"/>
    </visual>
  </link>
  <joint name="shift7" type="fixed">
    <parent link="link7b"/>
    <child link="link7c"/>
    <origin rpy="0 0 0" xyz="0 0 0.2025"/>
  </joint>
  <link name="link7c">
    </link>
  <joint name="joint8a" type="continuous">
    <parent link="link7c"/>
    <child link="link8a"/>
    <origin rpy="0 0 3.141592653589793" xyz="0 0 0"/>
    <axis xyz="0 0 1"/>
  </joint>
  <link name="link8a">
    <inertial>
      <origin rpy="0 0 0" xyz="0 -0.03 0.12"/>
      <mass value="4"/>
      <inertia ixx="0.1" ixy="0" ixz="0" iyy="0.09" iyz="0" izz="0.02"/>
    </inertial>
    <visual>
      <origin rpy="0 0 0" xyz="0 0 0"/>
      <geometry>
        <mesh filename="package://snakebot/meshes/link.stl"/>
      </geometry>
      <material name="Orange"/>
    </visual>
  </link>
  <joint name="joint8b" type="continuous">
    <parent link="link8a"/>
    <child link="link8b"/>
    <origin rpy="0 0 0" xyz="0 0 0.2025"/>
    <axis xyz="0 1 0"/>
  </joint>
  <link name="link8b">
    <inertial>
      <origin rpy="3.141592653589793 0 0" xyz="0 0.03 0.08250000000000002"/>
      <mass value="4"/>
      <inertia ixx="0.1" ixy="0" ixz="0" iyy="0.09" iyz="0" izz="0.02"/>
    </inertial>
    <visual>
      <origin rpy="3.141592653589793 0 0" xyz="0 0 0.2025"/>
      <geometry>
        <mesh filename="package://snakebot/meshes/link.stl"/>
      </geometry>
      <material name="Orange"/>
    </visual>
  </link>
  <joint name="shift8" type="fixed">
    <parent link="link8b"/>
    <child link="link8c"/>
    <origin rpy="0 0 0" xyz="0 0 0.2025"/>
  </joint>
  <link name="link8c">
    </link>
  <joint name="joint9a" type="continuous">
    <parent link="link8c"/>
    <child link="link9a"/>
    <origin rpy="0 0 3.141592653589793" xyz="0 0 0"/>
    <axis xyz="0 0 1"/>
  </joint>
  <link name="link9a">
    <inertial>
      <origin rpy="0 0 0" xyz="0 -0.03 0.12"/>
      <mass value="4"/>
      <inertia ixx="0.1" ixy="0" ixz="0" iyy="0.09" iyz="0" izz="0.02"/>
    </inertial>
    <visual>
      <origin rpy="0 0 0" xyz="0 0 0"/>
      <geometry>
        <mesh filename="package://snakebot/meshes/link.stl"/>
      </geometry>
      <material name="Orange"/>
    </visual>
  </link>
  <joint name="joint9b" type="continuous">
    <parent link="link9a"/>
    <child link="link9b"/>
    <origin rpy="0 0 0" xyz="0 0 0.2025"/>
    <axis xyz="0 1 0"/>
  </joint>
  <link name="link9b">
    <inertial>
      <origin rpy="3.141592653589793 0 0" xyz="0 0.03 0.08250000000000002"/>
      <mass value="4"/>
      <inertia ixx="0.1" ixy="0" ixz="0" iyy="0.09" iyz="0" izz="0.02"/>
    </inertial>
    <visual>
      <origin rpy="3.141592653589793 0 0" xyz="0 0 0.2025"/>
      <geometry>
        <mesh filename="package://snakebot/meshes/link.stl"/>
      </geometry>
      <material name="Orange"/>
    </visual>
  </link>
  <joint name="shift9" type="fixed">
    <parent link="link9b"/>
    <child link="link9c"/>
    <origin rpy="0 0 0" xyz="0 0 0.2025"/>
  </joint>
  <link name="link9c">
    </link>
  <joint name="joint10a" type="continuous">
    <parent link="link9c"/>
    <child link="link10a"/>
    <origin rpy="0 0 3.141592653589793" xyz="0 0 0"/>
    <axis xyz="0 0 1"/>
  </joint>
  <link name="link10a">
    <inertial>
      <origin rpy="0 0 0" xyz="0 -0.03 0.12"/>
      <mass value="4"/>
      <inertia ixx="0.1" ixy="0" ixz="0" iyy="0.09" iyz="0" izz="0.02"/>
    </inertial>
    <visual>
      <origin rpy="0 0 0" xyz="0 0 0"/>
      <geometry>
        <mesh filename="package://snakebot/meshes/link.stl"/>
      </geometry>
      <material name="Orange"/>
    </visual>
  </link>
  <joint name="joint10b" type="continuous">
    <parent link="link10a"/>
    <child link="link10b"/>
    <origin rpy="0 0 0" xyz="0 0 0.2025"/>
    <axis xyz="0 1 0"/>
  </joint>
  <link name="link10b">
    <inertial>
      <origin rpy="3.141592653589793 0 0" xyz="0 0.03 0.08250000000000002"/>
      <mass value="4"/>
      <inertia ixx="0.1" ixy="0" ixz="0" iyy="0.09" iyz="0" izz="0.02"/>
    </inertial>
    <visual>
      <origin rpy="3.141592653589793 0 0" xyz="0 0 0.2025"/>
      <geometry>
        <mesh filename="package://snakebot/meshes/link.stl"/>
      </geometry>
      <material name="Orange"/>
    </visual>
  </link>
  <joint name="shift10" type="fixed">
    <parent link="link10b"/>
    <child link="link10c"/>
    <origin rpy="0 0 0" xyz="0 0 0.2025"/>
  </joint>
  <link name="link10c">
    </link>
  <joint name="joint11a" type="continuous">
    <parent link="link10c"/>
    <child link="link11a"/>
    <origin rpy="0 0 3.141592653589793" xyz="0 0 0"/>
    <axis xyz="0 0 1"/>
  </joint>
  <link name="link11a">
    <inertial>
      <origin rpy="0 0 0" xyz="0 -0.03 0.12"/>
      <mass value="4"/>
      <inertia ixx="0.1" ixy="0" ixz="0" iyy="0.09" iyz="0" izz="0.02"/>
    </inertial>
    <visual>
      <origin rpy="0 0 0" xyz="0 0 0"/>
      <geometry>
        <mesh filename="package://snakebot/meshes/link.stl"/>
      </geometry>
      <material name="Orange"/>
    </visual>
  </link>
  <joint name="joint11b" type="continuous">
    <parent link="link11a"/>
    <child link="link11b"/>
    <origin rpy="0 0 0" xyz="0 0 0.2025"/>
    <axis xyz="0 1 0"/>
  </joint>
  <link name="link11b">
    <inertial>
      <origin rpy="3.141592653589793 0 0" xyz="0 0.03 0.08250000000000002"/>
      <mass value="4"/>
      <inertia ixx="0.1" ixy="0" ixz="0" iyy="0.09" iyz="0" izz="0.02"/>
    </inertial>
    <visual>
      <origin rpy="3.141592653589793 0 0" xyz="0 0 0.2025"/>
      <geometry>
        <mesh filename="package://snakebot/meshes/link.stl"/>
      </geometry>
      <material name="Orange"/>
    </visual>
  </link>
  <joint name="shift11" type="fixed">
    <parent link="link11b"/>
    <child link="link11c"/>
    <origin rpy="0 0 0" xyz="0 0 0.2025"/>
  </joint>
  <link name="link11c">
    </link>
  <joint name="joint12a" type="continuous">
    <parent link="link11c"/>
    <child link="link12a"/>
    <origin rpy="0 0 3.141592653589793" xyz="0 0 0"/>
    <axis xyz="0 0 1"/>
  </joint>
  <link name="link12a">
    <inertial>
      <origin rpy="0 0 0" xyz="0 -0.03 0.12"/>
      <mass value="4"/>
      <inertia ixx="0.1" ixy="0" ixz="0" iyy="0.09" iyz="0" izz="0.02"/>
    </inertial>
    <visual>
      <origin rpy="0 0 0" xyz="0 0 0"/>
      <geometry>
        <mesh filename="package://snakebot/meshes/link.stl"/>
      </geometry>
      <material name="Orange"/>
    </visual>
  </link>
  <joint name="joint12b" type="continuous">
    <parent link="link12a"/>
    <child link="link12b"/>
    <origin rpy="0 0 0" xyz="0 0 0.2025"/>
    <axis xyz="0 1 0"/>
  </joint>
  <link name="link12b">
    <inertial>
      <origin rpy="3.141592653589793 0 0" xyz="0 0.03 0.08250000000000002"/>
      <mass value="4"/>
      <inertia ixx="0.1" ixy="0" ixz="0" iyy="0.09" iyz="0" izz="0.02"/>
    </inertial>
    <visual>
      <origin rpy="3.141592653589793 0 0" xyz="0 0 0.2025"/>
      <geometry>
        <mesh filename="package://snakebot/meshes/link.stl"/>
      </geometry>
      <material name="Orange"/>
    </visual>
  </link>
  <joint name="shift12" type="fixed">
    <parent link="link12b"/>
    <child link="link12c"/>
    <origin rpy="0 0 0" xyz="0 0 0.2025"/>
  </joint>
  <link name="link12c">
    </link>
  <joint name="joint13a" type="continuous">
    <parent link="link12c"/>
    <child link="link13a"/>
    <origin rpy="0 0 3.141592653589793" xyz="0 0 0"/>
    <axis xyz="0 0 1"/>
  </joint>
  <link name="link13a">
    <inertial>
      <origin rpy="0 0 0" xyz="0 -0.03 0.12"/>
      <mass value="4"/>
      <inertia ixx="0.1" ixy="0" ixz="0" iyy="0.09" iyz="0" izz="0.02"/>
    </inertial>
    <visual>
      <origin rpy="0 0 0" xyz="0 0 0"/>
      <geometry>
        <mesh filename="package://snakebot/meshes/link.stl"/>
      </geometry>
      <material name="Orange"/>
    </visual>
  </link>
  <joint name="joint13b" type="continuous">
    <parent link="link13a"/>
    <child link="link13b"/>
    <origin rpy="0 0 0" xyz="0 0 0.2025"/>
    <axis xyz="0 1 0"/>
  </joint>
  <link name="link13b">
    <inertial>
      <origin rpy="3.141592653589793 0 0" xyz="0 0.03 0.08250000000000002"/>
      <mass value="4"/>
      <inertia ixx="0.1" ixy="0" ixz="0" iyy="0.09" iyz="0" izz="0.02"/>
    </inertial>
    <visual>
      <origin rpy="3.141592653589793 0 0" xyz="0 0 0.2025"/>
      <geometry>
        <mesh filename="package://snakebot/meshes/link.stl"/>
      </geometry>
      <material name="Orange"/>
    </visual>
  </link>
  <joint name="shift13" type="fixed">
    <parent link="link13b"/>
    <child link="link13c"/>
    <origin rpy="0 0 0" xyz="0 0 0.2025"/>
  </joint>
  <link name="link13c">
    </link>
  <joint name="joint14a" type="continuous">
    <parent link="link13c"/>
    <child link="link14a"/>
    <origin rpy="0 0 3.141592653589793" xyz="0 0 0"/>
    <axis xyz="0 0 1"/>
  </joint>
  <link name="link14a">
    <inertial>
      <origin rpy="0 0 0" xyz="0 -0.03 0.12"/>
      <mass value="4"/>
      <inertia ixx="0.1" ixy="0" ixz="0" iyy="0.09" iyz="0" izz="0.02"/>
    </inertial>
    <visual>
      <origin rpy="0 0 0" xyz="0 0 0"/>
      <geometry>
        <mesh filename="package://snakebot/meshes/link.stl"/>
      </geometry>
      <material name="Orange"/>
    </visual>
  </link>
  <joint name="joint14b" type="continuous">
    <parent link="link14a"/>
    <child link="link14b"/>
    <origin rpy="0 0 0" xyz="0 0 0.2025"/>
    <axis xyz="0 1 0"/>
  </joint>
  <link name="link14b">
    <inertial>
      <origin rpy="3.141592653589793 0 0" xyz="0 0.03 0.08250000000000002"/>
      <mass value="4"/>
      <inertia ixx="0.1" ixy="0" ixz="0" iyy="0.09" iyz="0" izz="0.02"/>
    </inertial>
    <visual>
      <origin rpy="3.141592653589793 0 0" xyz="0 0 0.2025"/>
      <geometry>
        <mesh filename="package://snakebot/meshes/link.stl"/>
      </geometry>
      <material name="Orange"/>
    </visual>
  </link>
  <joint name="shift14" type="fixed">
    <parent link="link14b"/>
    <child link="link14c"/>
    <origin rpy="0 0 0" xyz="0 0 0.2025"/>
  </joint>
  <link name="link14c">
    </link>
  <joint name="joint15a" type="continuous">
    <parent link="link14c"/>
    <child link="link15a"/>
    <origin rpy="0 0 3.141592653589793" xyz="0 0 0"/>
    <axis xyz="0 0 1"/>
  </joint>
  <link name="link15a">
    <inertial>
      <origin rpy="0 0 0" xyz="0 -0.03 0.12"/>
      <mass value="4"/>
      <inertia ixx="0.1" ixy="0" ixz="0" iyy="0.09" iyz="0" izz="0.02"/>
    </inertial>
    <visual>
      <origin rpy="0 0 0" xyz="0 0 0"/>
      <geometry>
        <mesh filename="package://snakebot/meshes/link.stl"/>
      </geometry>
      <material name="Orange"/>
    </visual>
  </link>
  <joint name="joint15b" type="continuous">
    <parent link="link15a"/>
    <child link="link15b"/>
    <origin rpy="0 0 0" xyz="0 0 0.2025"/>
    <axis xyz="0 1 0"/>
  </joint>
  <link name="link15b">
    <inertial>
      <origin rpy="3.141592653589793 0 0" xyz="0 0.03 0.08250000000000002"/>
      <mass value="4"/>
      <inertia ixx="0.1" ixy="0" ixz="0" iyy="0.09" iyz="0" izz="0.02"/>
    </inertial>
    <visual>
      <origin rpy="3.141592653589793 0 0" xyz="0 0 0.2025"/>
      <geometry>
        <mesh filename="package://snakebot/meshes/link.stl"/>
      </geometry>
      <material name="Orange"/>
    </visual>
  </link>
  <joint name="shift15" type="fixed">
    <parent link="link15b"/>
    <child link="link15c"/>
    <origin rpy="0 0 0" xyz="0 0 0.2025"/>
  </joint>
  <link name="link15c">
    </link>
  <joint name="joint16a" type="continuous">
    <parent link="link15c"/>
    <child link="link16a"/>
    <origin rpy="0 0 3.141592653589793" xyz="0 0 0"/>
    <axis xyz="0 0 1"/>
  </joint>
  <link name="link16a">
    <inertial>
      <origin rpy="0 0 0" xyz="0 -0.03 0.12"/>
      <mass value="4"/>
      <inertia ixx="0.1" ixy="0" ixz="0" iyy="0.09" iyz="0" izz="0.02"/>
    </inertial>
    <visual>
      <origin rpy="0 0 0" xyz="0 0 0"/>
      <geometry>
        <mesh filename="package://snakebot/meshes/link.stl"/>
      </geometry>
      <material name="Orange"/>
    </visual>
  </link>
  <joint name="joint16b" type="continuous">
    <parent link="link16a"/>
    <child link="link16b"/>
    <origin rpy="0 0 0" xyz="0 0 0.2025"/>
    <axis xyz="0 1 0"/>
  </joint>
  <link name="link16b">
    <inertial>
      <origin rpy="3.141592653589793 0 0" xyz="0 0.03 0.08250000000000002"/>
      <mass value="4"/>
      <inertia ixx="0.1" ixy="0" ixz="0" iyy="0.09" iyz="0" izz="0.02"/>
    </inertial>
    <visual>
      <origin rpy="3.141592653589793 0 0" xyz="0 0 0.2025"/>
      <geometry>
        <mesh filename="package://snakebot/meshes/link.stl"/>
      </geometry>
      <material name="Orange"/>
    </visual>
  </link>
  <joint name="shift16" type="fixed">
    <parent link="link16b"/>
    <child link="link16c"/>
    <origin rpy="0 0 0" xyz="0 0 0.2025"/>
  </joint>
  <link name="link16c">
    </link>
  <joint name="joint17a" type="continuous">
    <parent link="link16c"/>
    <child link="link17a"/>
    <origin rpy="0 0 3.141592653589793" xyz="0 0 0"/>
    <axis xyz="0 0 1"/>
  </joint>
  <link name="link17a">
    <inertial>
      <origin rpy="0 0 0" xyz="0 -0.03 0.12"/>
      <mass value="4"/>
      <inertia ixx="0.1" ixy="0" ixz="0" iyy="0.09" iyz="0" izz="0.02"/>
    </inertial>
    <visual>
      <origin rpy="0 0 0" xyz="0 0 0"/>
      <geometry>
        <mesh filename="package://snakebot/meshes/link.stl"/>
      </geometry>
      <material name="Orange"/>
    </visual>
  </link>
  <joint name="joint17b" type="continuous">
    <parent link="link17a"/>
    <child link="link17b"/>
    <origin rpy="0 0 0" xyz="0 0 0.2025"/>
    <axis xyz="0 1 0"/>
  </joint>
  <link name="link17b">
    <inertial>
      <origin rpy="3.141592653589793 0 0" xyz="0 0.03 0.08250000000000002"/>
      <mass value="4"/>
      <inertia ixx="0.1" ixy="0" ixz="0" iyy="0.09" iyz="0" izz="0.02"/>
    </inertial>
    <visual>
      <origin rpy="3.141592653589793 0 0" xyz="0 0 0.2025"/>
      <geometry>
        <mesh filename="package://snakebot/meshes/link.stl"/>
      </geometry>
      <material name="Orange"/>
    </visual>
  </link>
  <joint name="shift17" type="fixed">
    <parent link="link17b"/>
    <child link="link17c"/>
    <origin rpy="0 0 0" xyz="0 0 0.2025"/>
  </joint>
  <link name="link17c">
    </link>
  <joint name="joint18a" type="continuous">
    <parent link="link17c"/>
    <child link="link18a"/>
    <origin rpy="0 0 3.141592653589793" xyz="0 0 0"/>
    <axis xyz="0 0 1"/>
  </joint>
  <link name="link18a">
    <inertial>
      <origin rpy="0 0 0" xyz="0 -0.03 0.12"/>
      <mass value="4"/>
      <inertia ixx="0.1" ixy="0" ixz="0" iyy="0.09" iyz="0" izz="0.02"/>
    </inertial>
    <visual>
      <origin rpy="0 0 0" xyz="0 0 0"/>
      <geometry>
        <mesh filename="package://snakebot/meshes/link.stl"/>
      </geometry>
      <material name="Orange"/>
    </visual>
  </link>
  <joint name="joint18b" type="continuous">
    <parent link="link18a"/>
    <child link="link18b"/>
    <origin rpy="0 0 0" xyz="0 0 0.2025"/>
    <axis xyz="0 1 0"/>
  </joint>
  <link name="link18b">
    <inertial>
      <origin rpy="3.141592653589793 0 0" xyz="0 0.03 0.08250000000000002"/>
      <mass value="4"/>
      <inertia ixx="0.1" ixy="0" ixz="0" iyy="0.09" iyz="0" izz="0.02"/>
    </inertial>
    <visual>
      <origin rpy="3.141592653589793 0 0" xyz="0 0 0.2025"/>
      <geometry>
        <mesh filename="package://snakebot/meshes/link.stl"/>
      </geometry>
      <material name="Orange"/>
    </visual>
  </link>
  <joint name="shift18" type="fixed">
    <parent link="link18b"/>
    <child link="link18c"/>
    <origin rpy="0 0 0" xyz="0 0 0.2025"/>
  </joint>
  <link name="link18c">
    </link>
  <joint name="joint19a" type="continuous">
    <parent link="link18c"/>
    <child link="link19a"/>
    <origin rpy="0 0 3.141592653589793" xyz="0 0 0"/>
    <axis xyz="0 0 1"/>
  </joint>
  <link name="link19a">
    <inertial>
      <origin rpy="0 0 0" xyz="0 -0.03 0.12"/>
      <mass value="4"/>
      <inertia ixx="0.1" ixy="0" ixz="0" iyy="0.09" iyz="0" izz="0.02"/>
    </inertial>
    <visual>
      <origin rpy="0 0 0" xyz="0 0 0"/>
      <geometry>
        <mesh filename="package://snakebot/meshes/link.stl"/>
      </geometry>
      <material name="Orange"/>
    </visual>
  </link>
  <joint name="joint19b" type="continuous">
    <parent link="link19a"/>
    <child link="link19b"/>
    <origin rpy="0 0 0" xyz="0 0 0.2025"/>
    <axis xyz="0 1 0"/>
  </joint>
  <link name="link19b">
    <inertial>
      <origin rpy="3.141592653589793 0 0" xyz="0 0.03 0.08250000000000002"/>
      <mass value="4"/>
      <inertia ixx="0.1" ixy="0" ixz="0" iyy="0.09" iyz="0" izz="0.02"/>
    </inertial>
    <visual>
      <origin rpy="3.141592653589793 0 0" xyz="0 0 0.2025"/>
      <geometry>
        <mesh filename="package://snakebot/meshes/link.stl"/>
      </geometry>
      <material name="Orange"/>
    </visual>
  </link>
  <joint name="shift19" type="fixed">
    <parent link="link19b"/>
    <child link="link19c"/>
    <origin rpy="0 0 0" xyz="0 0 0.2025"/>
  </joint>
  <link name="link19c">
    </link>
  <joint name="joint20a" type="continuous">
    <parent link="link19c"/>
    <child link="link20a"/>
    <origin rpy="0 0 3.141592653589793" xyz="0 0 0"/>
    <axis xyz="0 0 1"/>
  </joint>
  <link name="link20a">
    <inertial>
      <origin rpy="0 0 0" xyz="0 -0.03 0.12"/>
      <mass value="4"/>
      <inertia ixx="0.1" ixy="0" ixz="0" iyy="0.09" iyz="0" izz="0.02"/>
    </inertial>
    <visual>
      <origin rpy="0 0 0" xyz="0 0 0"/>
      <geometry>
        <mesh filename="package://snakebot/meshes/link.stl"/>
      </geometry>
      <material name="Orange"/>
    </visual>
  </link>
  <joint name="joint20b" type="continuous">
    <parent link="link20a"/>
    <child link="link20b"/>
    <origin rpy="0 0 0" xyz="0 0 0.2025"/>
    <axis xyz="0 1 0"/>
  </joint>
  <link name="link20b">
    <inertial>
      <origin rpy="3.141592653589793 0 0" xyz="0 0.03 0.08250000000000002"/>
      <mass value="4"/>
      <inertia ixx="0.1" ixy="0" ixz="0" iyy="0.09" iyz="0" izz="0.02"/>
    </inertial>
    <visual>
      <origin rpy="3.141592653589793 0 0" xyz="0 0 0.2025"/>
      <geometry>
        <mesh filename="package://snakebot/meshes/link.stl"/>
      </geometry>
      <material name="Orange"/>
    </visual>
  </link>
  <joint name="shift20" type="fixed">
    <parent link="link20b"/>
    <child link="link20c"/>
    <origin rpy="0 0 0" xyz="0 0 0.2025"/>
  </joint>
  <link name="link20c">
    </link>
  <joint name="attach-mating-plate" type="fixed">
    <parent link="link20c"/>
    <child link="mating-plate"/>
    <origin  xyz="0 0 0"  rpy="0 0 0" />
  </joint>
  <link name="mating-plate">
    <visual>
      <geometry>
        <cylinder length="0.001" radius="0.086"/>
      </geometry>
      <material name="Grey"/>
    </visual>
  </link>
  <joint name="attach-flange" type="fixed">
    <parent link="mating-plate"/>
    <child link="flange"/>
    <origin  xyz="0 0 0"  rpy="0 0 0" />
  </joint>
  <link name="flange">
    <inertial>
      <origin rpy="0 0 0" xyz="0 0 0.02"/>
      <mass value="0.42857142857142855"/>
      <!--this is for the MFT Pneumatisch flange-->
      <inertia ixx="0.01" ixy="0" ixz="0" iyy="0.01" iyz="0" izz="0.01"/>
    </inertial>
    <visual>
      <geometry>
        <mesh filename="package://snakebot/meshes/flange.stl"/>
      </geometry>
      <material name="Grey"/>
    </visual>
  </link>
  <joint name="finalspin" type="continuous">
    <parent link="flange"/>
    <child link="tip"/>
    <origin rpy="0 0 0" xyz="0 0 0.045"/>
    <axis xyz="0 0 1"/>
  </joint>
  <link name="tip"/>


<!-- Attach Fingers and Cube*** -->

 <joint name="attach-palm" type="fixed">
    <parent link="tip"/>
    <child  link="palm"/>
  </joint>
  <link name="palm">
    <visual>
      <origin xyz="0 0 0" rpy="0 1.5708 0"/>
      <geometry>
    <cylinder length="0.25" radius="0.02"/>
      </geometry>
      <material name="black"/>
    </visual>
    <collision>
      <origin xyz="0 0 0" rpy="0 1.5708 0"/>
      <geometry>
    <cylinder length="0.1" radius="0.01"/>
      </geometry>
    </collision>
    <inertial>
      <origin xyz="0 0.1 0" rpy="0 1.5708 0"/>
      <mass value="0.05"/>
      <inertia
        ixx="0.000043" ixy="0.0" ixz="0.0"
        iyy="0.000043" iyz="0.0"
        izz="0.000003"/>
    </inertial>
  </link>

  <joint name="attach-leftfinger" type="fixed">
    <parent link="tip"/>
    <child  link="leftfinger"/>
  </joint>
  <link name="leftfinger">
    <visual>
      <origin xyz="-0.12 0 0.1" rpy="0 0 0"/>
      <geometry>
    <cylinder length="0.17" radius="0.02"/>
      </geometry>
      <material name="black"/>
    </visual>
    <inertial>
      <origin xyz="-0.1 0 0" rpy="0 0 0"/>
      <mass value="0.05"/>
      <inertia
        ixx="0.000022" ixy="0.0" ixz="0.0"
        iyy="0.000022" iyz="0.0"
        izz="0.000002"/>
    </inertial>
  </link>

  <joint name="attach-rightfinger" type="fixed">
    <parent link="tip"/>
    <child  link="rightfinger"/>
  </joint>
  <link name="rightfinger">
    <visual>
      <origin xyz="0.12 0 0.1" rpy="0 0 0"/>
      <geometry>
    <cylinder length="0.17" radius="0.02"/>
      </geometry>
      <material name="black"/>
    </visual>
    <inertial>
      <origin xyz="0.1 0 0.14" rpy="0 0 0"/>
      <mass value="0.05"/>
      <inertia
        ixx="0.000022" ixy="0.0" ixz="0.0"
        iyy="0.000022" iyz="0.0"
        izz="0.000002"/>
    </inertial>
  </link>

  <!-- *** Cube: Six sides *** -->

  <joint name="attach-cube" type="fixed">
    <parent link="tip"/>
    <child  link="cube"/>
  </joint>
  <link name="cube">
    <collision>
      <origin xyz="0 0 0.0" rpy="0 0 0"/>
      <geometry>
    <box size="0.2 0.2 0.20"/>
      </geometry>
    </collision>
    <inertial>
      <origin xyz="0 0 0" rpy="0 0 0"/>
      <mass value="1.0"/>
      <inertia
        ixx="0.000120" ixy="0.0" ixz="0.0"
        iyy="0.000120" iyz="0.0"
        izz="0.000120"/>
    </inertial>
  </link>

  <joint name="attach-cube-xp" type="fixed">
    <parent link="cube"/>
    <child  link="cube-xp"/>
  </joint>
  <link name="cube-xp">
    <visual>
      <origin         xyz=" 0.08   0    0.1"    rpy="0 0 0"/>
      <geometry> <box size="0.0404 0.18 0.18"/> </geometry>
      <material name="white"/>
    </visual>
  </link>

  <joint name="attach-cube-xm" type="fixed">
    <parent link="cube"/>
    <child  link="cube-xm"/>
  </joint>
  <link name="cube-xm">
    <visual>
      <origin         xyz="-0.08   0    0.1"    rpy="0 0 0"/>
      <geometry> <box size="0.0404 0.18 0.18"/> </geometry>
      <material name="yellow"/>
    </visual>
  </link>

  <joint name="attach-cube-yp" type="fixed">
    <parent link="cube"/>
    <child  link="cube-yp"/>
  </joint>
  <link name="cube-yp">
    <visual>
      <origin         xyz=" 0    0.08   0.1"    rpy="0 0 0"/>
      <geometry> <box size="0.18 0.0404 0.18"/> </geometry>
      <material name="green"/>
    </visual>
  </link>

  <joint name="attach-cube-ym" type="fixed">
    <parent link="cube"/>
    <child  link="cube-ym"/>
  </joint>
  <link name="cube-ym">
    <visual>
      <origin         xyz=" 0   -0.08   0.1"    rpy="0 0 0"/>
      <geometry> <box size="0.18 0.0404 0.18"/> </geometry>
      <material name="blue"/>
    </visual>
  </link>

  <joint name="attach-cube-zp" type="fixed">
    <parent link="cube"/>
    <child  link="cube-zp"/>
  </joint>
  <link name="cube-zp">
    <visual>
      <origin         xyz=" 0    0    0.18"   rpy="0 0 0"/>
      <geometry> <box size="0.18 0.18 0.0404"/> </geometry>
      <material name="red"/>
    </visual>
  </link>

  <joint name="attach-cube-zm" type="fixed">
    <parent link="cube"/>
    <child  link="cube-zm"/>
  </joint>
  <link name="cube-zm">
    <visual>
      <origin         xyz=" 0    0   0.02"   rpy="0 0 0"/>
      <geometry> <box size="0.18 0.18 0.0404"/> </geometry>
      <material name="orange"/>
    </visual>
  </link>




</robot>
