<?xml version="1.0" ?>
<!-- =================================================================================== -->
<!-- |    This document was autogenerated by xacro from snakebot.urdf.xacro            | -->
<!-- |    EDITING THIS FILE BY HAND IS NOT RECOMMENDED                                 | -->
<!-- =================================================================================== -->
<robot name="snakebot">


  <!-- *************************************************** -->
  <!-- ******************* RVIZ Colors ******************* -->
  <!-- *************************************************** -->

  <material name="white">    <color rgba="1.00 1.00 1.00 1"/>  </material>
  <material name="gray">     <color rgba="0.60 0.60 0.60 1"/>  </material>
  <material name="table">    <color rgba="0.85 0.77 0.77 1"/>  </material>
  <material name="black">    <color rgba="0.00 0.00 0.00 1"/>  </material>

  <material name="red">      <color rgba="1.00 0.00 0.00 1"/>  </material>
  <material name="green">    <color rgba="0.00 1.00 0.00 1"/>  </material>
  <material name="blue">     <color rgba="0.00 0.00 1.00 1"/>  </material>

  <material name="cyan">     <color rgba="0.00 1.00 1.00 1"/>  </material>
  <material name="magenta">  <color rgba="1.00 0.00 1.00 1"/>  </material>
  <material name="yellow">   <color rgba="1.00 1.00 0.00 1"/>  </material>

  <material name="orange">   <color rgba="1.00 0.65 0.00 1"/>  </material>



  <!-- *************************************************** -->
  <!-- ******************* PARAMETERS ******************** -->
  <!-- *************************************************** -->
  <material name="Grey">
    <color rgba="0.4 0.4 0.4 1.0"/>
  </material>
  <material name="Red">
    <color rgba="0.82 0.06 0.06 1.0"/>
  </material>
  <material name="Orange">
    <color rgba="1.0 0.4235294117647059 0.0392156862745098 1.0"/>
  </material>
  <!-- *************************************************** -->
  <!-- ******************** BASE MACRO ******************* -->
  <!-- *************************************************** -->
  <!-- *************************************************** -->
  <!-- *************** PAIR OF JOINTS MACRO ************** -->
  <!-- *************************************************** -->
  <!-- *************************************************** -->
  <!-- ***************** TIP FLANGE MACRO **************** -->
  <!-- *************************************************** -->
  <!-- *************************************************** -->
  <!-- ********************** ROBOT ********************** -->
  <!-- *************************************************** -->
  <link name="world"/>
  <joint name="attach-base" type="fixed">
    <parent link="world"/>
    <child link="link0b"/>
  </joint>
  <link name="link0b">
    <visual>
      <geometry>
        <mesh filename="package://snakebot/meshes/base.stl"/>
      </geometry>
      <material name="Grey"/>
    </visual>
  </link>
  <joint name="shift0" type="fixed">
    <parent link="link0b"/>
    <child link="link0c"/>
    <origin rpy="0 0 0" xyz="0 0 0.1575"/>
  </joint>
  <link name="link0c">
    </link>
  <joint name="joint1a" type="continuous">
    <parent link="link0c"/>
    <child link="link1a"/>
    <origin rpy="0 0 3.141592653589793" xyz="0 0 0"/>
    <axis xyz="0 0 1"/>
  </joint>
  <link name="link1a">
    <inertial>
      <origin rpy="0 0 0" xyz="0 -0.03 0.12"/>
      <mass value="4"/>
      <inertia ixx="0.1" ixy="0" ixz="0" iyy="0.09" iyz="0" izz="0.02"/>
    </inertial>
    <visual>
      <origin rpy="0 0 0" xyz="0 0 0"/>
      <geometry>
        <mesh filename="package://snakebot/meshes/link.stl"/>
      </geometry>
      <material name="Orange"/>
    </visual>
  </link>
  <joint name="joint1b" type="continuous">
    <parent link="link1a"/>
    <child link="link1b"/>
    <origin rpy="0 0 0" xyz="0 0 0.2025"/>
    <axis xyz="0 1 0"/>
  </joint>
  <link name="link1b">
    <inertial>
      <origin rpy="3.141592653589793 0 0" xyz="0 0.03 0.08250000000000002"/>
      <mass value="4"/>
      <inertia ixx="0.1" ixy="0" ixz="0" iyy="0.09" iyz="0" izz="0.02"/>
    </inertial>
    <visual>
      <origin rpy="3.141592653589793 0 0" xyz="0 0 0.2025"/>
      <geometry>
        <mesh filename="package://snakebot/meshes/link.stl"/>
      </geometry>
      <material name="Orange"/>
    </visual>
  </link>
  <joint name="shift1" type="fixed">
    <parent link="link1b"/>
    <child link="link1c"/>
    <origin rpy="0 0 0" xyz="0 0 0.2025"/>
  </joint>
  <link name="link1c">
    </link>
  <joint name="joint2a" type="continuous">
    <parent link="link1c"/>
    <child link="link2a"/>
    <origin rpy="0 0 3.141592653589793" xyz="0 0 0"/>
    <axis xyz="0 0 1"/>
  </joint>
  <link name="link2a">
    <inertial>
      <origin rpy="0 0 0" xyz="0 -0.03 0.12"/>
      <mass value="4"/>
      <inertia ixx="0.1" ixy="0" ixz="0" iyy="0.09" iyz="0" izz="0.02"/>
    </inertial>
    <visual>
      <origin rpy="0 0 0" xyz="0 0 0"/>
      <geometry>
        <mesh filename="package://snakebot/meshes/link.stl"/>
      </geometry>
      <material name="Orange"/>
    </visual>
  </link>
  <joint name="joint2b" type="continuous">
    <parent link="link2a"/>
    <child link="link2b"/>
    <origin rpy="0 0 0" xyz="0 0 0.2025"/>
    <axis xyz="0 1 0"/>
  </joint>
  <link name="link2b">
    <inertial>
      <origin rpy="3.141592653589793 0 0" xyz="0 0.03 0.08250000000000002"/>
      <mass value="4"/>
      <inertia ixx="0.1" ixy="0" ixz="0" iyy="0.09" iyz="0" izz="0.02"/>
    </inertial>
    <visual>
      <origin rpy="3.141592653589793 0 0" xyz="0 0 0.2025"/>
      <geometry>
        <mesh filename="package://snakebot/meshes/link.stl"/>
      </geometry>
      <material name="Orange"/>
    </visual>
  </link>
  <joint name="shift2" type="fixed">
    <parent link="link2b"/>
    <child link="link2c"/>
    <origin rpy="0 0 0" xyz="0 0 0.2025"/>
  </joint>
  <link name="link2c">
    </link>
  <joint name="joint3a" type="continuous">
    <parent link="link2c"/>
    <child link="link3a"/>
    <origin rpy="0 0 3.141592653589793" xyz="0 0 0"/>
    <axis xyz="0 0 1"/>
  </joint>
  <link name="link3a">
    <inertial>
      <origin rpy="0 0 0" xyz="0 -0.03 0.12"/>
      <mass value="4"/>
      <inertia ixx="0.1" ixy="0" ixz="0" iyy="0.09" iyz="0" izz="0.02"/>
    </inertial>
    <visual>
      <origin rpy="0 0 0" xyz="0 0 0"/>
      <geometry>
        <mesh filename="package://snakebot/meshes/link.stl"/>
      </geometry>
      <material name="Orange"/>
    </visual>
  </link>
  <joint name="joint3b" type="continuous">
    <parent link="link3a"/>
    <child link="link3b"/>
    <origin rpy="0 0 0" xyz="0 0 0.2025"/>
    <axis xyz="0 1 0"/>
  </joint>
  <link name="link3b">
    <inertial>
      <origin rpy="3.141592653589793 0 0" xyz="0 0.03 0.08250000000000002"/>
      <mass value="4"/>
      <inertia ixx="0.1" ixy="0" ixz="0" iyy="0.09" iyz="0" izz="0.02"/>
    </inertial>
    <visual>
      <origin rpy="3.141592653589793 0 0" xyz="0 0 0.2025"/>
      <geometry>
        <mesh filename="package://snakebot/meshes/link.stl"/>
      </geometry>
      <material name="Orange"/>
    </visual>
  </link>
  <joint name="shift3" type="fixed">
    <parent link="link3b"/>
    <child link="link3c"/>
    <origin rpy="0 0 0" xyz="0 0 0.2025"/>
  </joint>
  <link name="link3c">
    </link>
  <joint name="joint4a" type="continuous">
    <parent link="link3c"/>
    <child link="link4a"/>
    <origin rpy="0 0 3.141592653589793" xyz="0 0 0"/>
    <axis xyz="0 0 1"/>
  </joint>
  <link name="link4a">
    <inertial>
      <origin rpy="0 0 0" xyz="0 -0.03 0.12"/>
      <mass value="4"/>
      <inertia ixx="0.1" ixy="0" ixz="0" iyy="0.09" iyz="0" izz="0.02"/>
    </inertial>
    <visual>
      <origin rpy="0 0 0" xyz="0 0 0"/>
      <geometry>
        <mesh filename="package://snakebot/meshes/link.stl"/>
      </geometry>
      <material name="Orange"/>
    </visual>
  </link>
  <joint name="joint4b" type="continuous">
    <parent link="link4a"/>
    <child link="link4b"/>
    <origin rpy="0 0 0" xyz="0 0 0.2025"/>
    <axis xyz="0 1 0"/>
  </joint>
  <link name="link4b">
    <inertial>
      <origin rpy="3.141592653589793 0 0" xyz="0 0.03 0.08250000000000002"/>
      <mass value="4"/>
      <inertia ixx="0.1" ixy="0" ixz="0" iyy="0.09" iyz="0" izz="0.02"/>
    </inertial>
    <visual>
      <origin rpy="3.141592653589793 0 0" xyz="0 0 0.2025"/>
      <geometry>
        <mesh filename="package://snakebot/meshes/link.stl"/>
      </geometry>
      <material name="Orange"/>
    </visual>
  </link>
  <joint name="shift4" type="fixed">
    <parent link="link4b"/>
    <child link="link4c"/>
    <origin rpy="0 0 0" xyz="0 0 0.2025"/>
  </joint>
  <link name="link4c">
    </link>
  <joint name="attach-mating-plate" type="fixed">
    <parent link="link4c"/>
    <child link="mating-plate"/>
  </joint>
  <link name="mating-plate">
    <visual>
      <geometry>
        <cylinder length="0.001" radius="0.086"/>
      </geometry>
      <material name="Grey"/>
    </visual>
  </link>
  <joint name="attach-flange" type="fixed">
    <parent link="mating-plate"/>
    <child link="flange"/>
  </joint>
  <link name="flange">
    <inertial>
      <origin rpy="0 0 0" xyz="0 0 0.02"/>
      <mass value="0.42857142857142855"/>
      <!--this is for the MFT Pneumatisch flange-->
      <inertia ixx="0.01" ixy="0" ixz="0" iyy="0.01" iyz="0" izz="0.01"/>
    </inertial>
    <visual>
      <geometry>
        <mesh filename="package://snakebot/meshes/flange.stl"/>
      </geometry>
      <material name="Grey"/>
    </visual>
  </link>
  <joint name="finalspin" type="continuous">
    <parent link="flange"/>
    <child link="tip"/>
    <origin rpy="0 0 0" xyz="0 0 0.045"/>
    <axis xyz="0 0 1"/>
  </joint>
  <link name="tip"/>


  
<!-- Attach Fingers and Cube*** -->

 <joint name="attach-palm" type="fixed">
    <parent link="tip"/>
    <child  link="palm"/>
  </joint>
  <link name="palm">
    <visual>
      <origin xyz="0 0 0" rpy="0 1.5708 0"/>
      <geometry>
    <cylinder length="0.25" radius="0.02"/>
      </geometry>
      <material name="black"/>
    </visual>
    <collision>
      <origin xyz="0 0 0" rpy="0 1.5708 0"/>
      <geometry>
    <cylinder length="0.1" radius="0.01"/>
      </geometry>
    </collision>
    <inertial>
      <origin xyz="0 0.1 0" rpy="0 1.5708 0"/>
      <mass value="0.05"/>
      <inertia
        ixx="0.000043" ixy="0.0" ixz="0.0"
        iyy="0.000043" iyz="0.0"
        izz="0.000003"/>
    </inertial>
  </link>

  <joint name="attach-leftfinger" type="fixed">
    <parent link="tip"/>
    <child  link="leftfinger"/>
  </joint>
  <link name="leftfinger">
    <visual>
      <origin xyz="-0.12 0 0.1" rpy="0 0 0"/>
      <geometry>
    <cylinder length="0.17" radius="0.02"/>
      </geometry>
      <material name="black"/>
    </visual>
    <inertial>
      <origin xyz="-0.1 0 0" rpy="0 0 0"/>
      <mass value="0.05"/>
      <inertia
        ixx="0.000022" ixy="0.0" ixz="0.0"
        iyy="0.000022" iyz="0.0"
        izz="0.000002"/>
    </inertial>
  </link>

  <joint name="attach-rightfinger" type="fixed">
    <parent link="tip"/>
    <child  link="rightfinger"/>
  </joint>
  <link name="rightfinger">
    <visual>
      <origin xyz="0.12 0 0.1" rpy="0 0 0"/>
      <geometry>
    <cylinder length="0.17" radius="0.02"/>
      </geometry>
      <material name="black"/>
    </visual>
    <inertial>
      <origin xyz="0.1 0 0.14" rpy="0 0 0"/>
      <mass value="0.05"/>
      <inertia
        ixx="0.000022" ixy="0.0" ixz="0.0"
        iyy="0.000022" iyz="0.0"
        izz="0.000002"/>
    </inertial>
  </link>

  <!-- *** Cube: Six sides *** -->

  <joint name="attach-cube" type="fixed">
    <parent link="tip"/>
    <child  link="cube"/>
  </joint>
  <link name="cube">
    <collision>
      <origin xyz="0 0 0.0" rpy="0 0 0"/>
      <geometry>
    <box size="0.2 0.2 0.20"/>
      </geometry>
    </collision>
    <inertial>
      <origin xyz="0 0 0" rpy="0 0 0"/>
      <mass value="1.0"/>
      <inertia
        ixx="0.000120" ixy="0.0" ixz="0.0"
        iyy="0.000120" iyz="0.0"
        izz="0.000120"/>
    </inertial>
  </link>

  <joint name="attach-cube-xp" type="fixed">
    <parent link="cube"/>
    <child  link="cube-xp"/>
  </joint>
  <link name="cube-xp">
    <visual>
      <origin         xyz=" 0.08   0    0.1"    rpy="0 0 0"/>
      <geometry> <box size="0.0404 0.18 0.18"/> </geometry>
      <material name="blue"/>
    </visual>
  </link>

  <joint name="attach-cube-xm" type="fixed">
    <parent link="cube"/>
    <child  link="cube-xm"/>
  </joint>
  <link name="cube-xm">
    <visual>
      <origin         xyz="-0.08   0    0.1"    rpy="0 0 0"/>
      <geometry> <box size="0.0404 0.18 0.18"/> </geometry>
      <material name="green"/>
    </visual>
  </link>

  <joint name="attach-cube-yp" type="fixed">
    <parent link="cube"/>
    <child  link="cube-yp"/>
  </joint>
  <link name="cube-yp">
    <visual>
      <origin         xyz=" 0    0.08   0.1"    rpy="0 0 0"/>
      <geometry> <box size="0.18 0.0404 0.18"/> </geometry>
      <material name="white"/>
    </visual>
  </link>

  <joint name="attach-cube-ym" type="fixed">
    <parent link="cube"/>
    <child  link="cube-ym"/>
  </joint>
  <link name="cube-ym">
    <visual>
      <origin         xyz=" 0   -0.08   0.1"    rpy="0 0 0"/>
      <geometry> <box size="0.18 0.0404 0.18"/> </geometry>
      <material name="yellow"/>
    </visual>
  </link>

  <joint name="attach-cube-zp" type="fixed">
    <parent link="cube"/>
    <child  link="cube-zp"/>
  </joint>
  <link name="cube-zp">
    <visual>
      <origin         xyz=" 0    0    0.18"   rpy="0 0 0"/>
      <geometry> <box size="0.18 0.18 0.0404"/> </geometry>
      <material name="red"/>
    </visual>
  </link>

  <joint name="attach-cube-zm" type="fixed">
    <parent link="cube"/>
    <child  link="cube-zm"/>
  </joint>
  <link name="cube-zm">
    <visual>
      <origin         xyz=" 0    0   0.02"   rpy="0 0 0"/>
      <geometry> <box size="0.18 0.18 0.0404"/> </geometry>
      <material name="orange"/>
    </visual>
  </link>


</robot>
